<?xml version="1.0"?>  
<robot name="mybot" xmlns:xacro="http://ros.org/wiki/xacro">  

  <xacro:include filename="$(find bingda_tutorials)/urdf/mybot.gazebo.xacro" /> 
  <link name="base_footprint"/>

  <joint name="base_joint" type="fixed">  
    <parent link="base_footprint"/>  
    <child link="base_link"/>  
    <origin rpy="0 0 0" xyz="0 0 0"/>  
  </joint>  
  
  <link name="base_link">  
    <inertial>
     <origin xyz="0 0 0" rpy="0 0 0"/>
     <mass value="2.0"/>
     <inertia ixx="0.0001"  ixy="0"  ixz="0" iyy="0.0001" iyz="0" izz="0.001" />
    </inertial>

    <visual>  
      <geometry>  
        <box size="0.25 0.25 0.35"/>  
      </geometry>  
      <origin rpy="0 0 0" xyz="0 0 0"/>  
      <material name="blue">  
          <color rgba="0 0 0.8 1"/>  
      </material>  
    </visual>  

   <collision>
     <origin xyz="0 0 0" rpy="0 0 0"/>
     <geometry>
       <box size="0.25 0.25 0.35"/>
     </geometry>
   </collision>

  </link>  
 
  <link name="right_wheel_link">  
    <inertial>
     <origin xyz="0 0 0" rpy="0 0 0"/>
     <mass value="0.2"/>
     <inertia ixx="0.0001"  ixy="0"  ixz="0" iyy="0.0001" iyz="0" izz="0.0001" />
    </inertial>

    <visual>  
      <geometry>  
        <cylinder length="0.05" radius="0.03"/>  
      </geometry>  
      <material name="black">  
        <color rgba="0 0 0 1"/>  
      </material>  
    </visual>  

    <collision>
     <origin xyz="0 0 0" rpy="0 0 0"/>
     <geometry>
       <cylinder length="0.05" radius="0.03"/> 
     </geometry>
    </collision>
  </link>  
 
  <joint name="right_wheel_joint" type="continuous">  
    <axis xyz="0 0 -1"/>  
    <parent link="base_link"/>  
    <child link="right_wheel_link"/>  
    <origin rpy="1.5707 0 0" xyz="0.125 -0.15 -0.175"/>  
  </joint>  
 
  <link name="left_wheel_link">  
    <inertial>
     <origin xyz="0 0 0" rpy="0 0 0"/>
     <mass value="0.2"/>
     <inertia ixx="0.0001"  ixy="0"  ixz="0" iyy="0.0001" iyz="0" izz="0.0001" />
    </inertial>

    <visual>  
      <geometry>  
        <cylinder length="0.05" radius="0.03"/>  
      </geometry>  
      <material name="black">  
        <color rgba="0 0 0 1"/>  
      </material>  
    </visual>  

    <collision>
     <origin xyz="0 0 0" rpy="0 0 0"/>
     <geometry>
       <cylinder length="0.05" radius="0.03"/> 
     </geometry>
    </collision>   
  </link>  
 
  <joint name="left_wheel_joint" type="continuous">  
    <axis xyz="0 0 -1"/>  
    <parent link="base_link"/>  
    <child link="left_wheel_link"/>  
    <origin rpy="1.5707 0 0" xyz="0.125 0.15 -0.175"/>  
  </joint>  
 
  <link name="ball_wheel_link">  
    <inertial>
     <origin xyz="0 0 0" rpy="0 0 0"/>
     <mass value="0.2"/>
     <inertia ixx="0"  ixy="0"  ixz="0" iyy="0" iyz="0" izz="0" />
    </inertial>

    <visual>  
      <geometry>  
        <sphere radius="0.03"/>  
      </geometry>  
      <material name="black">  
        <color rgba="0 0 0 1"/>  
      </material>  
    </visual>  

    <collision>
     <origin xyz="0 0 0" rpy="0 0 0"/>
     <geometry>
       <sphere radius="0.03"/> 
     </geometry>
    </collision>   
  </link>  

  <joint name="ball_wheel_joint" type="fixed">  
    <axis xyz="0 0 1"/>  
    <parent link="base_link"/>  
    <child link="ball_wheel_link"/>  
    <origin rpy="0 0 0" xyz="-0.08 0 -0.175"/>  
  </joint>   
  <!-- imu sensor -->
  <link name="imu">  
    <visual>  
      <geometry>  
        <box size="0.01 0.01 0.01"/>  
      </geometry>  
      <material name="white">  
          <color rgba="1 1 1 1"/>  
      </material>  
    </visual>  
  </link>  

  <joint name="imu_joint" type="fixed">  
    <parent link="base_link"/>  
    <child link="imu"/>  
    <origin xyz="0.08 0 0.175"/>  
  </joint> 

  <!-- camera -->
  <link name="base_camera_link">  
    <visual>  
      <geometry>  
        <box size="0.02 0.03 0.03"/>  
      </geometry>  
      <material name="white">  
          <color rgba="1 1 1 1"/>  
      </material>  
    </visual>  
  </link>  

  <joint name="camera_joint" type="fixed">  
    <parent link="base_link"/>  
    <child link="base_camera_link"/>  
    <origin xyz="0.1 0 0.175"/>  
  </joint> 
  <!-- laser lidar -->
  <link name="base_laser_link">  
    <visual>  
      <geometry>  
        <cylinder length="0.06" radius="0.04"/>   
      </geometry>  
      <material name="white">  
          <color rgba="1 1 1 1"/>  
      </material>  
    </visual>  
  </link>  
  
  <joint name="laser_joint" type="fixed">  
    <parent link="base_link"/>  
    <child link="base_laser_link"/>  
    <origin xyz="0 0.0 0.175"/>  
  </joint> 
  
  <!-- Logical Audio -->
  <link name="base_audio_link_1">  
    <visual>  
      <geometry>  
        <sphere radius="0.025"/>  
      </geometry>  
      <material name="blue">  
        <color rgba="0 0 0 1"/>  
      </material>  
    </visual>   
  </link>  
  
  <joint name="base_audio_link_1" type="fixed">  
    <parent link="base_link"/>  
    <child link="base_audio_link_1"/>  
    <origin xyz="0.125 0.125 -0.1"/>  
  </joint> 
  
    <link name="base_audio_link_2">  
    <visual>  
      <geometry>  
        <sphere radius="0.025"/>  
      </geometry>  
      <material name="blue">  
        <color rgba="0 0 0 1"/>  
      </material>  
    </visual>   
  </link>  
  
  <joint name="base_audio_link_2" type="fixed">  
    <parent link="base_link"/>  
    <child link="base_audio_link_2"/>  
    <origin xyz="0.125 -0.125 -0.1"/>  
  </joint> 

  <link name="base_audio_link_3">  
    <visual>  
      <geometry>  
        <sphere radius="0.025"/>  
      </geometry>  
      <material name="blue">  
        <color rgba="0 0 0 1"/>  
      </material>  
    </visual>   
  </link>  
  
  <joint name="base_audio_link_3" type="fixed">  
    <parent link="base_link"/>  
    <child link="base_audio_link_3"/>  
    <origin xyz="-0.125 -0.125 -0.1"/>  
  </joint> 

  <link name="base_audio_link_4">  
    <visual>  
      <geometry>  
        <sphere radius="0.025"/>  
      </geometry>  
      <material name="blue">  
        <color rgba="0 0 0 1"/>  
      </material>  
    </visual>   
  </link>  
  
  <joint name="base_audio_link_4" type="fixed">  
    <parent link="base_link"/>  
    <child link="base_audio_link_4"/>  
    <origin xyz="-0.125 0.125 -0.1"/>  
  </joint> 
  
  <link name="base_RFID_link_r">  
    <visual>  
      <geometry>  
        <box size="0.001 0.001 0.2"/>  
      </geometry>  
      <material name="blue">  
        <color rgba="0 0 0 1"/>  
      </material>  
    </visual>   
  </link>  
  
  <joint name="base_RFID_link_r" type="fixed">  
    <parent link="base_link"/>  
    <child link="base_RFID_link_r"/>  
    <origin xyz="-0.1 -0.1 0.275"/>  
  </joint> 


</robot>
